<mujoco model="base">
  <compiler angle="radian" meshdir="meshes/"/>
  <option impratio="20" density="1.2" viscosity="2e-05" cone="elliptic"/>
  <size njmax="5000" nconmax="5000"/>
  <visual>
    <map znear="0.001"/>
  </visual>
  <asset>
    <texture type="skybox" builtin="gradient" rgb1="0.9 0.9 1" rgb2="0.2 0.3 0.4" width="256" height="1536"/>
    <texture type="2d" name="texplane" file="/home/johnathant/VIOLA-master/assets/./textures/wood-tiles.png"/>
    <texture type="cube" name="tex-ceramic" file="/home/johnathant/VIOLA-master/assets/./textures/ceramic.png"/>
    <texture type="cube" name="tex-steel-brushed" file="/home/johnathant/VIOLA-master/assets/./textures/steel-brushed.png"/>
    <texture type="2d" name="tex-cream-plaster" file="/home/johnathant/VIOLA-master/assets/./textures/cream-plaster.png"/>
    <texture type="cube" name="textable" builtin="flat" rgb1="0.5 0.5 0.5" width="512" height="3072"/>
    <texture type="2d" name="skillet_tex-metal" file="/home/johnathant/VIOLA-master/envs/objects/meshes/metal.png"/>
    <texture type="2d" name="wooden-spoon_tex-metal" file="/home/johnathant/VIOLA-master/envs/objects/./wooden-spoon/Material.wooden-spoon_Base_Color.png"/>
    <material name="floorplane" texture="texplane" texuniform="true" texrepeat="2 2" specular="0" shininess="0" reflectance="0.01"/>
    <material name="table_ceramic" texture="tex-ceramic" specular="0.2" shininess="0"/>
    <material name="table_legs_metal" texture="tex-steel-brushed" shininess="0.8" reflectance="0.8"/>
    <material name="walls_mat" texture="tex-cream-plaster" texuniform="true" texrepeat="3 3" specular="0.1" shininess="0.1"/>
    <material name="table_mat" texture="textable"/>
    <material name="robot0_Black" shininess="0.25" rgba="0.033102 0.033102 0.033102 1"/>
    <material name="robot0_JointGrey" shininess="0.25" rgba="0.278431 0.278431 0.278431 1"/>
    <material name="robot0_LinkGrey" shininess="0.25" rgba="0.820392 0.820392 0.820392 1"/>
    <material name="robot0_URBlue" shininess="0.25" rgba="0.490196 0.678431 0.8 1"/>
    <material name="skillet_wood" texture="skillet_tex-metal" reflectance="0.5"/>
    <material name="skillet_default_mat" specular="0" shininess="0" rgba="0.2 0.2 0.2 1"/>
    <material name="wooden-spoon_wood" texture="wooden-spoon_tex-metal" reflectance="0.5"/>
    <material name="wooden-spoon_default_mat" specular="0" shininess="0" rgba="0.2 0.2 0.2 1"/>
    <mesh name="robot0_link1" file="/home/johnathant/VIOLA-master/robots/models/meshes/link1.stl" scale="0.001 0.001 0.001"/>
    <mesh name="robot0_link2" file="/home/johnathant/VIOLA-master/robots/models/meshes/link2.stl" scale="0.001 0.001 0.001"/>
    <mesh name="robot0_link3_papras_simple" file="/home/johnathant/VIOLA-master/robots/models/meshes/link3_papras_simple.stl" scale="0.001 0.001 0.001"/>
    <mesh name="robot0_link4_papras_simple" file="/home/johnathant/VIOLA-master/robots/models/meshes/link4_papras_simple.stl" scale="0.001 0.001 0.001"/>
    <mesh name="robot0_link5" file="/home/johnathant/VIOLA-master/robots/models/meshes/link5.stl" scale="0.001 0.001 0.001"/>
    <mesh name="robot0_link6_papras_simple" file="/home/johnathant/VIOLA-master/robots/models/meshes/link6_papras_simple.stl" scale="0.001 0.001 0.001"/>
    <mesh name="robot0_end_link" file="/home/johnathant/VIOLA-master/robots/models/meshes/end_link.stl" scale="0.001 0.001 0.001"/>
    <mesh name="robot0_gripper_main_link" file="/home/johnathant/VIOLA-master/robots/models/meshes/gripper_main_link.stl" scale="0.001 0.001 0.001"/>
    <mesh name="robot0_gripper_link" file="/home/johnathant/VIOLA-master/robots/models/meshes/gripper_link.stl" scale="0.001 0.001 0.001"/>
    <mesh name="robot0_gripper_sub_link" file="/home/johnathant/VIOLA-master/robots/models/meshes/gripper_sub_link.stl" scale="0.001 0.001 0.001"/>
    <mesh name="robot0_camera_mount_simple" file="/home/johnathant/VIOLA-master/robots/models/meshes/camera_mount_simple.stl"/>
    <mesh name="mount0_pedestal" file="/home/johnathant/anaconda3/envs/ros/lib/python3.8/site-packages/robosuite/models/assets/mounts/meshes/rethink_mount/pedestal.stl"/>
    <mesh name="gripper0_robotiq_arg2f_base_link" file="/home/johnathant/anaconda3/envs/ros/lib/python3.8/site-packages/robosuite/models/assets/grippers/meshes/robotiq_85_gripper/robotiq_arg2f_base_link.stl"/>
    <mesh name="gripper0_robotiq_arg2f_85_outer_knuckle" file="/home/johnathant/anaconda3/envs/ros/lib/python3.8/site-packages/robosuite/models/assets/grippers/meshes/robotiq_85_gripper/robotiq_arg2f_85_outer_knuckle.stl" scale="0.001 0.001 0.001"/>
    <mesh name="gripper0_robotiq_arg2f_85_outer_finger" file="/home/johnathant/anaconda3/envs/ros/lib/python3.8/site-packages/robosuite/models/assets/grippers/meshes/robotiq_85_gripper/robotiq_arg2f_85_outer_finger.stl" scale="0.001 0.001 0.001"/>
    <mesh name="gripper0_robotiq_arg2f_85_inner_finger" file="/home/johnathant/anaconda3/envs/ros/lib/python3.8/site-packages/robosuite/models/assets/grippers/meshes/robotiq_85_gripper/robotiq_arg2f_85_inner_finger.stl" scale="0.001 0.001 0.001"/>
    <mesh name="gripper0_robotiq_arg2f_85_inner_knuckle" file="/home/johnathant/anaconda3/envs/ros/lib/python3.8/site-packages/robosuite/models/assets/grippers/meshes/robotiq_85_gripper/robotiq_arg2f_85_inner_knuckle.stl" scale="0.001 0.001 0.001"/>
    <mesh name="gripper0_robotiq_arg2f_85_outer_knuckle_vis" file="/home/johnathant/anaconda3/envs/ros/lib/python3.8/site-packages/robosuite/models/assets/grippers/meshes/robotiq_85_gripper/robotiq_arg2f_85_outer_knuckle_vis.stl" scale="0.001 0.001 0.001"/>
    <mesh name="gripper0_robotiq_arg2f_85_outer_finger_vis" file="/home/johnathant/anaconda3/envs/ros/lib/python3.8/site-packages/robosuite/models/assets/grippers/meshes/robotiq_85_gripper/robotiq_arg2f_85_outer_finger_vis.stl" scale="0.001 0.001 0.001"/>
    <mesh name="gripper0_robotiq_arg2f_85_inner_finger_vis" file="/home/johnathant/anaconda3/envs/ros/lib/python3.8/site-packages/robosuite/models/assets/grippers/meshes/robotiq_85_gripper/robotiq_arg2f_85_inner_finger_vis.stl" scale="0.001 0.001 0.001"/>
    <mesh name="gripper0_robotiq_arg2f_85_inner_knuckle_vis" file="/home/johnathant/anaconda3/envs/ros/lib/python3.8/site-packages/robosuite/models/assets/grippers/meshes/robotiq_85_gripper/robotiq_arg2f_85_inner_knuckle_vis.stl" scale="0.001 0.001 0.001"/>
    <mesh name="skillet_mesh" file="/home/johnathant/VIOLA-master/envs/objects/./skillet/skillet/skillet.obj" scale="0.0015 0.0015 0.0015"/>
    <mesh name="skillet_collision_0" file="/home/johnathant/VIOLA-master/envs/objects/./skillet/skillet/skillet_collision_0.obj"/>
    <mesh name="skillet_collision_1" file="/home/johnathant/VIOLA-master/envs/objects/./skillet/skillet/skillet_collision_1.obj"/>
    <mesh name="skillet_collision_2" file="/home/johnathant/VIOLA-master/envs/objects/./skillet/skillet/skillet_collision_2.obj"/>
    <mesh name="skillet_collision_3" file="/home/johnathant/VIOLA-master/envs/objects/./skillet/skillet/skillet_collision_3.obj"/>
    <mesh name="skillet_collision_4" file="/home/johnathant/VIOLA-master/envs/objects/./skillet/skillet/skillet_collision_4.obj"/>
    <mesh name="skillet_collision_5" file="/home/johnathant/VIOLA-master/envs/objects/./skillet/skillet/skillet_collision_5.obj"/>
    <mesh name="skillet_collision_6" file="/home/johnathant/VIOLA-master/envs/objects/./skillet/skillet/skillet_collision_6.obj"/>
    <mesh name="skillet_collision_7" file="/home/johnathant/VIOLA-master/envs/objects/./skillet/skillet/skillet_collision_7.obj"/>
    <mesh name="skillet_collision_8" file="/home/johnathant/VIOLA-master/envs/objects/./skillet/skillet/skillet_collision_8.obj"/>
    <mesh name="skillet_collision_9" file="/home/johnathant/VIOLA-master/envs/objects/./skillet/skillet/skillet_collision_9.obj"/>
    <mesh name="skillet_collision_10" file="/home/johnathant/VIOLA-master/envs/objects/./skillet/skillet/skillet_collision_10.obj"/>
    <mesh name="skillet_collision_11" file="/home/johnathant/VIOLA-master/envs/objects/./skillet/skillet/skillet_collision_11.obj"/>
    <mesh name="skillet_collision_12" file="/home/johnathant/VIOLA-master/envs/objects/./skillet/skillet/skillet_collision_12.obj"/>
    <mesh name="skillet_collision_13" file="/home/johnathant/VIOLA-master/envs/objects/./skillet/skillet/skillet_collision_13.obj"/>
    <mesh name="skillet_collision_14" file="/home/johnathant/VIOLA-master/envs/objects/./skillet/skillet/skillet_collision_14.obj"/>
    <mesh name="skillet_collision_15" file="/home/johnathant/VIOLA-master/envs/objects/./skillet/skillet/skillet_collision_15.obj"/>
    <mesh name="skillet_collision_16" file="/home/johnathant/VIOLA-master/envs/objects/./skillet/skillet/skillet_collision_16.obj"/>
    <mesh name="skillet_collision_17" file="/home/johnathant/VIOLA-master/envs/objects/./skillet/skillet/skillet_collision_17.obj"/>
    <mesh name="skillet_collision_18" file="/home/johnathant/VIOLA-master/envs/objects/./skillet/skillet/skillet_collision_18.obj"/>
    <mesh name="skillet_collision_19" file="/home/johnathant/VIOLA-master/envs/objects/./skillet/skillet/skillet_collision_19.obj"/>
    <mesh name="skillet_collision_20" file="/home/johnathant/VIOLA-master/envs/objects/./skillet/skillet/skillet_collision_20.obj"/>
    <mesh name="skillet_collision_21" file="/home/johnathant/VIOLA-master/envs/objects/./skillet/skillet/skillet_collision_21.obj"/>
    <mesh name="skillet_collision_22" file="/home/johnathant/VIOLA-master/envs/objects/./skillet/skillet/skillet_collision_22.obj"/>
    <mesh name="skillet_collision_23" file="/home/johnathant/VIOLA-master/envs/objects/./skillet/skillet/skillet_collision_23.obj"/>
    <mesh name="skillet_collision_24" file="/home/johnathant/VIOLA-master/envs/objects/./skillet/skillet/skillet_collision_24.obj"/>
    <mesh name="skillet_collision_25" file="/home/johnathant/VIOLA-master/envs/objects/./skillet/skillet/skillet_collision_25.obj"/>
    <mesh name="skillet_collision_26" file="/home/johnathant/VIOLA-master/envs/objects/./skillet/skillet/skillet_collision_26.obj"/>
    <mesh name="skillet_collision_27" file="/home/johnathant/VIOLA-master/envs/objects/./skillet/skillet/skillet_collision_27.obj"/>
    <mesh name="skillet_collision_28" file="/home/johnathant/VIOLA-master/envs/objects/./skillet/skillet/skillet_collision_28.obj"/>
    <mesh name="skillet_collision_29" file="/home/johnathant/VIOLA-master/envs/objects/./skillet/skillet/skillet_collision_29.obj"/>
    <mesh name="skillet_collision_30" file="/home/johnathant/VIOLA-master/envs/objects/./skillet/skillet/skillet_collision_30.obj"/>
    <mesh name="skillet_collision_31" file="/home/johnathant/VIOLA-master/envs/objects/./skillet/skillet/skillet_collision_31.obj"/>
    <mesh name="skillet_collision_32" file="/home/johnathant/VIOLA-master/envs/objects/./skillet/skillet/skillet_collision_32.obj"/>
    <mesh name="wooden-spoon_mesh" file="/home/johnathant/VIOLA-master/envs/objects/./wooden-spoon/wooden-spoon/wooden-spoon.obj" scale="0.015 0.015 0.02"/>
    <mesh name="wooden-spoon_collision_0" file="/home/johnathant/VIOLA-master/envs/objects/./wooden-spoon/wooden-spoon/wooden-spoon_collision_0.obj" scale="0.015 0.015 0.02"/>
    <mesh name="wooden-spoon_collision_1" file="/home/johnathant/VIOLA-master/envs/objects/./wooden-spoon/wooden-spoon/wooden-spoon_collision_1.obj" scale="0.015 0.015 0.02"/>
  </asset>
  <worldbody>
    <geom name="floor" size="3 3 0.125" type="plane" material="floorplane"/>
    <geom name="wall_leftcorner_visual" size="1.06 1.5 0.01" pos="-1.25 2.25 1.5" quat="0.653281 0.653281 0.270598 0.270598" type="box" contype="0" conaffinity="0" group="1" material="walls_mat"/>
    <geom name="wall_rightcorner_visual" size="1.06 1.5 0.01" pos="-1.25 -2.25 1.5" quat="0.653281 0.653281 -0.270598 -0.270598" type="box" contype="0" conaffinity="0" group="1" material="walls_mat"/>
    <geom name="wall_left_visual" size="1.75 1.5 0.01" pos="1.25 3 1.5" quat="0.707107 0.707107 0 0" type="box" contype="0" conaffinity="0" group="1" material="walls_mat"/>
    <geom name="wall_right_visual" size="1.75 1.5 0.01" pos="1.25 -3 1.5" quat="0.707107 -0.707107 0 0" type="box" contype="0" conaffinity="0" group="1" material="walls_mat"/>
    <geom name="wall_rear_visual" size="1.5 1.5 0.01" pos="-2 0 1.5" quat="0.5 0.5 0.5 0.5" type="box" contype="0" conaffinity="0" group="1" material="walls_mat"/>
    <geom name="wall_front_visual" size="3 1.5 0.01" pos="3 0 1.5" quat="0.5 0.5 -0.5 -0.5" type="box" contype="0" conaffinity="0" group="1" material="walls_mat"/>
    <camera name="frontview" pos="0.456132 0 1.35035" quat="0.638018 0.30485 0.30485 0.638018"/>
    <camera name="birdview" pos="-0.2 0 3" quat="0.707107 0 0 0.707107"/>
    <camera name="agentview" pos="0.5 0 1.35" quat="0.653098 0.271041 0.271041 0.653098"/>
    <camera name="sideview" pos="-0.0565177 1.27612 1.48796" quat="0.00990507 0.00687796 0.591223 0.806418"/>
    <light name="light1" pos="1 1 4" dir="0 -0.14834 -0.988936" castshadow="false" diffuse="0.8 0.8 0.8"/>
    <light name="light2" pos="-3 -3 4" dir="0 -0.14834 -0.988936" castshadow="false" diffuse="0.8 0.8 0.8"/>
    <body name="table" pos="-0.2 0 0.875">
      <geom name="table_collision" size="0.5 0.4 0.025" type="box" friction="0.6" rgba="0.5 0.5 0 1"/>
      <geom name="table_visual" size="0.5 0.4 0.025" type="box" contype="0" conaffinity="0" group="1" material="table_ceramic"/>
      <geom name="table_leg1_visual" size="0.025 0.4375" pos="0.4 0.3 -0.4375" type="cylinder" contype="0" conaffinity="0" group="1" material="table_legs_metal"/>
      <geom name="table_leg2_visual" size="0.025 0.4375" pos="-0.4 0.3 -0.4375" type="cylinder" contype="0" conaffinity="0" group="1" material="table_legs_metal"/>
      <geom name="table_leg3_visual" size="0.025 0.4375" pos="-0.4 -0.3 -0.4375" type="cylinder" contype="0" conaffinity="0" group="1" material="table_legs_metal"/>
      <geom name="table_leg4_visual" size="0.025 0.4375" pos="0.4 -0.3 -0.4375" type="cylinder" contype="0" conaffinity="0" group="1" material="table_legs_metal"/>
      <site name="table_top" pos="0 0 0.025" size="0.001" rgba="0 0 0 0"/>
    </body>
    <body name="robot0_base" pos="-0.5 0 0.912">
      <inertial pos="0 0 0" mass="0" diaginertia="0 0 0"/>
      <geom name="robot0_g0_col" type="mesh" rgba="0 0.5 0 1" mesh="robot0_link1"/>
      <geom name="robot0_g0_vis" type="mesh" contype="0" conaffinity="0" group="1" material="robot0_LinkGrey" mesh="robot0_link1"/>
      <camera name="robot0_robotview" pos="1 0 0.4" quat="0.653098 0.271041 0.271041 0.653098"/>
      <body name="robot0_robot1/link2" pos="0 0 0.126">
        <inertial pos="0 0.0008 0.03183" mass="0.94658" diaginertia="1 1 1"/>
        <joint name="robot0_robot1/joint1" pos="0 0 0" axis="0 0 1" range="-3.14159 3.14159" actuatorfrcrange="-100 100" armature="5" damping="0.7" frictionloss="0.1"/>
        <geom name="robot0_g1_col" type="mesh" rgba="0 0.5 0 1" mesh="robot0_link2"/>
        <geom name="robot0_g1_vis" type="mesh" contype="0" conaffinity="0" group="1" material="robot0_LinkGrey" mesh="robot0_link2"/>
        <body name="robot0_robot1/link3" pos="0 0.069 0.033">
          <inertial pos="0.01768 -0.06881 0.20524" mass="1.3026" diaginertia="1 1 1"/>
          <joint name="robot0_robot1/joint2" pos="0 0 0" axis="0 1 0" range="-2 2" actuatorfrcrange="-100 100" armature="2.5" damping="0.7" frictionloss="0.1"/>
          <geom name="robot0_g2_col" pos="0.067 0.008 -0.019" quat="0.000796327 0 0 1" type="mesh" rgba="0 0.5 0 1" mesh="robot0_link3_papras_simple"/>
          <geom name="robot0_g2_vis" pos="0.067 0.008 -0.019" quat="0.000796327 0 0 1" type="mesh" contype="0" conaffinity="0" group="1" material="robot0_LinkGrey" mesh="robot0_link3_papras_simple"/>
          <body name="robot0_robot1/link4" pos="0.03 -0.0115 0.264">
            <inertial pos="0.12475 -0.05716 0.02979" mass="1.15977" diaginertia="1 1 1"/>
            <joint name="robot0_robot1/joint3" pos="0 0 0" axis="0 1 0" range="-3.14159 1.5708" actuatorfrcrange="-100 100" armature="1.66667" damping="0.7" frictionloss="0.1"/>
            <geom name="robot0_g3_col" pos="0.227 0.0085 -0.024" quat="0.000796327 0 0 1" type="mesh" rgba="0 0.5 0 1" mesh="robot0_link4_papras_simple"/>
            <geom name="robot0_g3_vis" pos="0.227 0.0085 -0.024" quat="0.000796327 0 0 1" type="mesh" contype="0" conaffinity="0" group="1" material="robot0_LinkGrey" mesh="robot0_link4_papras_simple"/>
            <body name="robot0_robot1/link5" pos="0.195 -0.0575 0.03">
              <inertial pos="0.05642 -0.00217 2e-05" mass="0.44688" diaginertia="1 1 1"/>
              <joint name="robot0_robot1/joint4" pos="0 0 0" axis="1 0 0" range="-2.74889 2.74889" actuatorfrcrange="-100 100" armature="1.25" damping="0.7" frictionloss="0.1"/>
              <geom name="robot0_g4_col" type="mesh" rgba="0 0.5 0 1" mesh="robot0_link5"/>
              <geom name="robot0_g4_vis" type="mesh" contype="0" conaffinity="0" group="1" material="robot0_LinkGrey" mesh="robot0_link5"/>
              <body name="robot0_robot1/link6" pos="0.063 0.045 0">
                <inertial pos="0.06831 -0.04457 0" mass="0.43273" diaginertia="1 1 1"/>
                <joint name="robot0_robot1/joint5" pos="0 0 0" axis="0 1 0" range="-1.5708 1.5708" actuatorfrcrange="-100 100" armature="1" damping="0.7" frictionloss="0.1"/>
                <geom name="robot0_g5_col" pos="-0.034 -0.098 -0.028" type="mesh" rgba="0 0.5 0 1" mesh="robot0_link6_papras_simple"/>
                <geom name="robot0_g5_vis" pos="-0.034 -0.098 -0.028" type="mesh" contype="0" conaffinity="0" group="1" material="robot0_LinkGrey" mesh="robot0_link6_papras_simple"/>
                <body name="robot0_robot1/end_link" pos="0.123 -0.045 0">
                  <inertial pos="0.0155548 0.00238111 0.00634774" quat="0.679934 0.19414 0.420576 0.568433" mass="0.61719" diaginertia="4.00045 4.00045 4.00001"/>
                  <joint name="robot0_robot1/joint6" pos="0 0 0" axis="1 0 0" range="-3.14159 3.14159" actuatorfrcrange="-100 100" armature="0.833333" damping="0.7" frictionloss="0.1"/>
                  <geom name="robot0_g6_col" type="mesh" rgba="0 0.5 0 1" mesh="robot0_end_link"/>
                  <geom name="robot0_g6_vis" type="mesh" contype="0" conaffinity="0" group="1" material="robot0_LinkGrey" mesh="robot0_end_link"/>
                  <geom name="robot0_g7_col" pos="0.007 0 0" type="mesh" rgba="0 0.5 0 1" mesh="robot0_gripper_main_link"/>
                  <geom name="robot0_g8_col" pos="0.0662 0.0167 0.04452" type="mesh" rgba="0 0.5 0 1" mesh="robot0_camera_mount_simple"/>
                  <body name="robot0_right_hand">
                    <site name="robot0_ee" pos="0 0 0" size="0.01" group="1" rgba="0 0 1 1"/>
                    <site name="robot0_ee_x" pos="0 0 0" quat="0.707105 0.707108 0 0" size="0.005 0.1" group="1" type="cylinder" rgba="1 0 0 0"/>
                    <site name="robot0_ee_z" pos="0 0 0" quat="0.707105 0 0 0.707108" size="0.005 0.1" group="1" type="cylinder" rgba="0 0 1 0"/>
                    <site name="robot0_ee_y" pos="0 0 0" quat="0.707105 0 0.707108 0" size="0.005 0.1" group="1" type="cylinder" rgba="0 1 0 0"/>
                    <camera name="robot0_eye_in_hand" pos="0.05 0 0" quat="0 0.707107 0.707107 0" fovy="75"/>
                    <body name="gripper0_robotiq_85_adapter_link">
                      <inertial pos="0 0 0" mass="0.01" diaginertia="0.001 0.001 0.001"/>
                      <geom name="gripper0_hand_visual" type="mesh" contype="0" conaffinity="0" group="1" rgba="0.1 0.1 0.1 1" mesh="gripper0_robotiq_arg2f_base_link"/>
                      <geom name="gripper0_hand_collision" type="mesh" rgba="0 0 0.5 1" mesh="gripper0_robotiq_arg2f_base_link"/>
                      <site name="gripper0_ft_frame" pos="0 0 0" size="0.01" group="1" rgba="1 0 0 1"/>
                      <body name="gripper0_eef" pos="0 0 0.145" quat="0.707107 0 0 -0.707107">
                        <site name="gripper0_grip_site" pos="0 0 0" size="0.01" group="1" rgba="1 0 0 0.5"/>
                        <site name="gripper0_ee_x" pos="0.1 0 0" quat="0.707105 0 0.707108 0" size="0.005 0.1" group="1" type="cylinder" rgba="1 0 0 0"/>
                        <site name="gripper0_ee_y" pos="0 0.1 0" quat="0.707105 0.707108 0 0" size="0.005 0.1" group="1" type="cylinder" rgba="0 1 0 0"/>
                        <site name="gripper0_ee_z" pos="0 0 0.1" size="0.005 0.1" group="1" type="cylinder" rgba="0 0 1 0"/>
                        <site name="gripper0_grip_site_cylinder" pos="0 0 0" size="0.005 10" group="1" type="cylinder" rgba="0 1 0 0.3"/>
                      </body>
                      <body name="gripper0_left_outer_knuckle" pos="0 -0.0306011 0.054904" quat="0 0 0 1">
                        <inertial pos="0.000163875 0.0554825 -0.0100755" quat="0.920541 0.390623 -0.00362953 0.00231744" mass="0.0311462" diaginertia="5.11372e-05 4.89464e-05 4.95906e-06"/>
                        <joint name="gripper0_finger_joint" pos="0 0 0" axis="1 0 0" limited="true" range="0 0.8"/>
                        <geom name="gripper0_left_outer_knuckle_visual" type="mesh" contype="0" conaffinity="0" group="1" rgba="0.792157 0.819608 0.933333 1" mesh="gripper0_robotiq_arg2f_85_outer_knuckle_vis"/>
                        <geom name="gripper0_left_outer_knuckle_collision" type="mesh" solref="0.01 0.25" rgba="0 0 0.5 1" mesh="gripper0_robotiq_arg2f_85_outer_knuckle"/>
                        <geom name="gripper0_left_outer_finger_visual" pos="0 0.0315 -0.0041" type="mesh" contype="0" conaffinity="0" group="1" rgba="0.1 0.1 0.1 1" mesh="gripper0_robotiq_arg2f_85_outer_finger_vis"/>
                        <geom name="gripper0_left_outer_finger_collision" pos="0 0.0315 -0.0041" type="mesh" solref="0.01 0.25" rgba="0 0 0.5 1" mesh="gripper0_robotiq_arg2f_85_outer_finger"/>
                        <body name="gripper0_left_inner_finger" pos="0 0.0376 0.043">
                          <inertial pos="0.000199506 0.0032692 0.00175282" quat="0.933621 0.35825 -0.00273441 0.00104851" mass="0.0156391" diaginertia="1.57977e-05 1.51089e-05 1.4647e-06"/>
                          <joint name="gripper0_left_inner_finger_joint" pos="0 0 0" axis="1 0 0" limited="true" range="-0.8757 0.8757"/>
                          <geom name="gripper0_left_inner_finger_visual" type="mesh" contype="0" conaffinity="0" group="1" rgba="0.1 0.1 0.1 1" mesh="gripper0_robotiq_arg2f_85_inner_finger_vis"/>
                          <geom name="gripper0_left_inner_finger_collision" type="mesh" solref="0.01 0.25" rgba="0 0 0.5 1" mesh="gripper0_robotiq_arg2f_85_inner_finger"/>
                          <geom name="gripper0_left_fingertip_visual" size="0.011 0.003175 0.01875" pos="0 -0.0220203 0.03242" type="box" contype="0" conaffinity="0" group="1" rgba="0.9 0.9 0.9 1"/>
                          <geom name="gripper0_left_fingertip_collision" size="0.011 0.003175 0.01875" pos="0 -0.0220203 0.03242" type="box" solref="0.01 0.25" rgba="0 0 0.5 1"/>
                          <geom name="gripper0_left_fingerpad_collision" size="0.01 0.001 0.01675" pos="0 -0.0245203 0.03242" type="box" rgba="0 0 0.5 1"/>
                        </body>
                      </body>
                      <body name="gripper0_left_inner_knuckle" pos="0 -0.0127 0.06142" quat="0 0 0 1">
                        <inertial pos="0.000123012 0.0507851 0.00103969" quat="0.497203 0.502496 -0.507943 0.492221" mass="0.0271177" diaginertia="2.83809e-05 2.61936e-05 2.81319e-06"/>
                        <joint name="gripper0_left_inner_knuckle_joint" pos="0 0 0" axis="1 0 0" limited="true" range="0 0.8757"/>
                        <geom name="gripper0_left_inner_knuckle_visual" type="mesh" contype="0" conaffinity="0" group="1" rgba="0.1 0.1 0.1 1" mesh="gripper0_robotiq_arg2f_85_inner_knuckle_vis"/>
                        <geom name="gripper0_left_inner_knuckle_collision" type="mesh" rgba="0 0 0.5 1" mesh="gripper0_robotiq_arg2f_85_inner_knuckle"/>
                      </body>
                      <body name="gripper0_right_outer_knuckle" pos="0 0.0306011 0.054904">
                        <inertial pos="0.000163875 0.0554825 -0.0100755" quat="0.920541 0.390623 -0.00362953 0.00231744" mass="0.0311462" diaginertia="5.11372e-05 4.89464e-05 4.95906e-06"/>
                        <joint name="gripper0_right_outer_knuckle_joint" pos="0 0 0" axis="1 0 0" limited="true" range="0 0.8"/>
                        <geom name="gripper0_right_outer_knuckle_visual" type="mesh" contype="0" conaffinity="0" group="1" rgba="0.792157 0.819608 0.933333 1" mesh="gripper0_robotiq_arg2f_85_outer_knuckle_vis"/>
                        <geom name="gripper0_right_outer_knuckle_collision" type="mesh" solref="0.01 0.25" rgba="0 0 0.5 1" mesh="gripper0_robotiq_arg2f_85_outer_knuckle"/>
                        <geom name="gripper0_right_outer_finger_visual" pos="0 0.0315 -0.0041" type="mesh" contype="0" conaffinity="0" group="1" rgba="0.1 0.1 0.1 1" mesh="gripper0_robotiq_arg2f_85_outer_finger_vis"/>
                        <geom name="gripper0_right_outer_finger_collision" pos="0 0.0315 -0.0041" type="mesh" solref="0.01 0.25" rgba="0 0 0.5 1" mesh="gripper0_robotiq_arg2f_85_outer_finger"/>
                        <body name="gripper0_right_inner_finger" pos="0 0.0376 0.043">
                          <inertial pos="0.000199506 0.0032692 0.00175282" quat="0.933621 0.35825 -0.00273441 0.00104851" mass="0.0156391" diaginertia="1.57977e-05 1.51089e-05 1.4647e-06"/>
                          <joint name="gripper0_right_inner_finger_joint" pos="0 0 0" axis="1 0 0" limited="true" range="-0.8757 0.8757"/>
                          <geom name="gripper0_right_inner_finger_visual" type="mesh" contype="0" conaffinity="0" group="1" rgba="0.1 0.1 0.1 1" mesh="gripper0_robotiq_arg2f_85_inner_finger_vis"/>
                          <geom name="gripper0_right_inner_finger_collision" type="mesh" solref="0.01 0.25" rgba="0 0 0.5 1" mesh="gripper0_robotiq_arg2f_85_inner_finger"/>
                          <geom name="gripper0_right_fingertip_visual" size="0.011 0.003175 0.01875" pos="0 -0.0220203 0.03242" type="box" contype="0" conaffinity="0" group="1" rgba="0.9 0.9 0.9 1"/>
                          <geom name="gripper0_right_fingertip_collision" size="0.011 0.003175 0.01875" pos="0 -0.0220203 0.03242" type="box" solref="0.01 0.25" rgba="0 0 0.5 1"/>
                          <geom name="gripper0_right_fingerpad_collision" size="0.01 0.001 0.01675" pos="0 -0.0245203 0.03242" type="box" rgba="0 0 0.5 1"/>
                        </body>
                      </body>
                      <body name="gripper0_right_inner_knuckle" pos="0 0.0127 0.06142">
                        <inertial pos="0.000123012 0.0507851 0.00103969" quat="0.497203 0.502496 -0.507943 0.492221" mass="0.0271177" diaginertia="2.83809e-05 2.61936e-05 2.81319e-06"/>
                        <joint name="gripper0_right_inner_knuckle_joint" pos="0 0 0" axis="1 0 0" limited="true" range="0 0.8757"/>
                        <geom name="gripper0_right_inner_knuckle_visual" type="mesh" contype="0" conaffinity="0" group="1" rgba="0.1 0.1 0.1 1" mesh="gripper0_robotiq_arg2f_85_inner_knuckle_vis"/>
                        <geom name="gripper0_right_inner_knuckle_collision" type="mesh" rgba="0 0 0.5 1" mesh="gripper0_robotiq_arg2f_85_inner_knuckle"/>
                      </body>
                    </body>
                  </body>
                </body>
              </body>
            </body>
          </body>
        </body>
      </body>
      <body name="mount0_base" pos="0 0 0.01">
        <body name="mount0_controller_box">
          <inertial pos="-0.325 0 -0.38" mass="46.64" diaginertia="1.71363 1.27988 0.809981"/>
          <geom name="mount0_controller_box_col" size="0.11 0.2 0.265" pos="-0.325 0 -0.38" type="box" rgba="0.5 0.5 0 1"/>
        </body>
        <body name="mount0_pedestal_feet">
          <inertial pos="-0.1225 0 -0.758" mass="167.09" diaginertia="8.16095 9.59375 15.0785"/>
          <geom name="mount0_pedestal_feet_col" size="0.385 0.35 0.155" pos="-0.1225 0 -0.758" type="box" rgba="0.5 0.5 0 1"/>
        </body>
        <body name="mount0_torso">
          <inertial pos="0 0 0" mass="0.0001" diaginertia="1e-08 1e-08 1e-08"/>
          <geom name="mount0_torso_vis" size="0.05 0.05 0.05" pos="0 0 -0.05" type="box" contype="0" conaffinity="0" group="1" rgba="0.2 0.2 0.2 1"/>
        </body>
        <body name="mount0_pedestal">
          <inertial pos="0 0 0" quat="0.659267 -0.259505 -0.260945 0.655692" mass="60.864" diaginertia="6.0869 5.81635 4.20915"/>
          <geom name="mount0_pedestal_vis" type="mesh" contype="0" conaffinity="0" group="1" rgba="0.2 0.2 0.2 1" mesh="mount0_pedestal"/>
          <geom name="mount0_pedestal_col" size="0.18 0.31" pos="-0.02 0 -0.29" type="cylinder" rgba="0.5 0.5 0 1"/>
        </body>
      </body>
    </body>
    <body name="skillet_main">
      <inertial pos="0 0 0" mass="4" diaginertia="0.5 0.5 0.5"/>
      <joint name="skillet_joint0" type="free" limited="false" actuatorfrclimited="false" damping="0.0005"/>
      <geom name="skillet_g0" type="mesh" contype="0" conaffinity="0" group="1" material="skillet_default_mat" mesh="skillet_mesh"/>
      <geom name="skillet_g1" type="mesh" group="1" friction="2.05 1.4 0.15" solimp="0.9 0.95 0.01" density="200" material="skillet_default_mat" mesh="skillet_collision_0"/>
      <geom name="skillet_g2" type="mesh" group="1" friction="2.05 1.4 0.15" solimp="0.9 0.95 0.01" density="200" material="skillet_default_mat" mesh="skillet_collision_1"/>
      <geom name="skillet_g3" type="mesh" group="1" friction="2.05 1.4 0.15" solimp="0.9 0.95 0.01" density="200" material="skillet_default_mat" mesh="skillet_collision_2"/>
      <geom name="skillet_g4" type="mesh" group="1" friction="2.05 1.4 0.15" solimp="0.9 0.95 0.01" density="200" material="skillet_default_mat" mesh="skillet_collision_3"/>
      <geom name="skillet_g5" type="mesh" group="1" friction="2.05 1.4 0.15" solimp="0.9 0.95 0.01" density="200" material="skillet_default_mat" mesh="skillet_collision_4"/>
      <geom name="skillet_g6" type="mesh" group="1" friction="2.05 1.4 0.15" solimp="0.9 0.95 0.01" density="200" material="skillet_default_mat" mesh="skillet_collision_5"/>
      <geom name="skillet_g7" type="mesh" group="1" friction="2.05 1.4 0.15" solimp="0.9 0.95 0.01" density="200" material="skillet_default_mat" mesh="skillet_collision_6"/>
      <geom name="skillet_g8" type="mesh" group="1" friction="2.05 1.4 0.15" solimp="0.9 0.95 0.01" density="200" material="skillet_default_mat" mesh="skillet_collision_7"/>
      <geom name="skillet_g9" type="mesh" group="1" friction="2.05 1.4 0.15" solimp="0.9 0.95 0.01" density="200" material="skillet_default_mat" mesh="skillet_collision_8"/>
      <geom name="skillet_g10" type="mesh" group="1" friction="2.05 1.4 0.15" solimp="0.9 0.95 0.01" density="200" material="skillet_default_mat" mesh="skillet_collision_9"/>
      <geom name="skillet_g11" type="mesh" group="1" friction="2.05 1.4 0.15" solimp="0.9 0.95 0.01" density="200" material="skillet_default_mat" mesh="skillet_collision_10"/>
      <geom name="skillet_g12" type="mesh" group="1" friction="2.05 1.4 0.15" solimp="0.9 0.95 0.01" density="200" material="skillet_default_mat" mesh="skillet_collision_11"/>
      <geom name="skillet_g13" type="mesh" group="1" friction="2.05 1.4 0.15" solimp="0.9 0.95 0.01" density="200" material="skillet_default_mat" mesh="skillet_collision_12"/>
      <geom name="skillet_g14" type="mesh" group="1" friction="2.05 1.4 0.15" solimp="0.9 0.95 0.01" density="200" material="skillet_default_mat" mesh="skillet_collision_13"/>
      <geom name="skillet_g15" type="mesh" group="1" friction="2.05 1.4 0.15" solimp="0.9 0.95 0.01" density="200" material="skillet_default_mat" mesh="skillet_collision_14"/>
      <geom name="skillet_g16" type="mesh" group="1" friction="2.05 1.4 0.15" solimp="0.9 0.95 0.01" density="200" material="skillet_default_mat" mesh="skillet_collision_15"/>
      <geom name="skillet_g17" type="mesh" group="1" friction="2.05 1.4 0.15" solimp="0.9 0.95 0.01" density="200" material="skillet_default_mat" mesh="skillet_collision_16"/>
      <geom name="skillet_g18" type="mesh" group="1" friction="2.05 1.4 0.15" solimp="0.9 0.95 0.01" density="200" material="skillet_default_mat" mesh="skillet_collision_17"/>
      <geom name="skillet_g19" type="mesh" group="1" friction="2.05 1.4 0.15" solimp="0.9 0.95 0.01" density="200" material="skillet_default_mat" mesh="skillet_collision_18"/>
      <geom name="skillet_g20" type="mesh" group="1" friction="2.05 1.4 0.15" solimp="0.9 0.95 0.01" density="200" material="skillet_default_mat" mesh="skillet_collision_19"/>
      <geom name="skillet_g21" type="mesh" group="1" friction="2.05 1.4 0.15" solimp="0.9 0.95 0.01" density="200" material="skillet_default_mat" mesh="skillet_collision_20"/>
      <geom name="skillet_g22" type="mesh" group="1" friction="2.05 1.4 0.15" solimp="0.9 0.95 0.01" density="200" material="skillet_default_mat" mesh="skillet_collision_21"/>
      <geom name="skillet_g23" type="mesh" group="1" friction="2.05 1.4 0.15" solimp="0.9 0.95 0.01" density="200" material="skillet_default_mat" mesh="skillet_collision_22"/>
      <geom name="skillet_g24" type="mesh" group="1" friction="2.05 1.4 0.15" solimp="0.9 0.95 0.01" density="200" material="skillet_default_mat" mesh="skillet_collision_23"/>
      <geom name="skillet_g25" type="mesh" group="1" friction="2.05 1.4 0.15" solimp="0.9 0.95 0.01" density="200" material="skillet_default_mat" mesh="skillet_collision_24"/>
      <geom name="skillet_g26" type="mesh" group="1" friction="2.05 1.4 0.15" solimp="0.9 0.95 0.01" density="200" material="skillet_default_mat" mesh="skillet_collision_25"/>
      <geom name="skillet_g27" type="mesh" group="1" friction="2.05 1.4 0.15" solimp="0.9 0.95 0.01" density="200" material="skillet_default_mat" mesh="skillet_collision_26"/>
      <geom name="skillet_g28" type="mesh" group="1" friction="2.05 1.4 0.15" solimp="0.9 0.95 0.01" density="200" material="skillet_default_mat" mesh="skillet_collision_27"/>
      <geom name="skillet_g29" type="mesh" group="1" friction="2.05 1.4 0.15" solimp="0.9 0.95 0.01" density="200" material="skillet_default_mat" mesh="skillet_collision_28"/>
      <geom name="skillet_g30" type="mesh" group="1" friction="2.05 1.4 0.15" solimp="0.9 0.95 0.01" density="200" material="skillet_default_mat" mesh="skillet_collision_29"/>
      <geom name="skillet_g31" type="mesh" group="1" friction="2.05 1.4 0.15" solimp="0.9 0.95 0.01" density="200" material="skillet_default_mat" mesh="skillet_collision_30"/>
      <geom name="skillet_g32" type="mesh" group="1" friction="2.05 1.4 0.15" solimp="0.9 0.95 0.01" density="200" material="skillet_default_mat" mesh="skillet_collision_31"/>
      <geom name="skillet_g33" type="mesh" group="1" friction="2.05 1.4 0.15" solimp="0.9 0.95 0.01" density="200" material="skillet_default_mat" mesh="skillet_collision_32"/>
      <site name="skillet_default_site" pos="0 0 0" size="0.002" rgba="1 0 0 0"/>
    </body>
    <body name="wooden-spoon_main">
      <inertial pos="0 0 0" mass="1" diaginertia="0.5 0.5 0.5"/>
      <joint name="wooden-spoon_joint0" type="free" limited="false" actuatorfrclimited="false" damping="0.0005"/>
      <geom name="wooden-spoon_g0" type="mesh" contype="0" conaffinity="0" group="1" material="wooden-spoon_wood" mesh="wooden-spoon_mesh"/>
      <geom name="wooden-spoon_g1" type="mesh" friction="10.05 1.4 0.1" solimp="0.9 0.95 0.01" density="200" rgba="0.5 0 0 1" mesh="wooden-spoon_collision_0"/>
      <geom name="wooden-spoon_g2" type="mesh" friction="10.05 1.4 0.1" solimp="0.9 0.95 0.01" density="200" rgba="0.5 0 0 1" mesh="wooden-spoon_collision_1"/>
      <geom name="wooden-spoon_g1_visual" type="mesh" contype="0" conaffinity="0" group="1" friction="10.05 1.4 0.1" solimp="0.9 0.95 0.01" mass="0" material="wooden-spoon_wood" mesh="wooden-spoon_collision_0"/>
      <geom name="wooden-spoon_g2_visual" type="mesh" contype="0" conaffinity="0" group="1" friction="10.05 1.4 0.1" solimp="0.9 0.95 0.01" mass="0" material="wooden-spoon_wood" mesh="wooden-spoon_collision_1"/>
      <site name="wooden-spoon_default_site" pos="0 0 0" size="0.002" rgba="1 0 0 0"/>
    </body>
  </worldbody>
  <contact>
    <exclude body1="robot0_base" body2="robot0_robot1/link2"/>
  </contact>
  <tendon>
    <fixed name="gripper0_finger2_12_cpl" limited="true" range="-1 1" stiffness="0.4" springlength="0.001">
      <joint joint="gripper0_finger_joint" coef="1"/>
      <joint joint="gripper0_left_inner_finger_joint" coef="-3"/>
      <joint joint="gripper0_left_inner_knuckle_joint" coef="1"/>
    </fixed>
    <fixed name="gripper0_finger1_12_cpl" limited="true" range="-1 1" stiffness="0.4" springlength="0.001">
      <joint joint="gripper0_right_outer_knuckle_joint" coef="1"/>
      <joint joint="gripper0_right_inner_finger_joint" coef="-3"/>
      <joint joint="gripper0_right_inner_knuckle_joint" coef="1"/>
    </fixed>
  </tendon>
  <actuator>
    <general name="robot0_torq_j1" joint="robot0_robot1/joint1" ctrllimited="true" ctrlrange="-150 150"/>
    <general name="robot0_torq_j2" joint="robot0_robot1/joint2" ctrllimited="true" ctrlrange="-150 150"/>
    <general name="robot0_torq_j3" joint="robot0_robot1/joint3" ctrllimited="true" ctrlrange="-150 150"/>
    <general name="robot0_torq_j4" joint="robot0_robot1/joint4" ctrllimited="true" ctrlrange="-28 28"/>
    <general name="robot0_torq_j5" joint="robot0_robot1/joint5" ctrllimited="true" ctrlrange="-28 28"/>
    <general name="robot0_torq_j6" joint="robot0_robot1/joint6" ctrllimited="true" ctrlrange="-28 28"/>
    <general name="gripper0_finger_1" joint="gripper0_finger_joint" ctrllimited="true" ctrlrange="0 0.8" biastype="affine" gainprm="20" biasprm="0 -20"/>
    <general name="gripper0_finger_2" joint="gripper0_right_outer_knuckle_joint" ctrllimited="true" ctrlrange="0 0.8" biastype="affine" gainprm="20" biasprm="0 -20"/>
  </actuator>
  <sensor>
    <force site="gripper0_ft_frame" name="gripper0_force_ee"/>
    <torque site="gripper0_ft_frame" name="gripper0_torque_ee"/>
  </sensor>
</mujoco>
